<?xml version=" "?>
<robot name = "my_robot" xmlns:xacro ="http://www.ros.org/wiki/xacro">
	<xacro:property name="polelen" value="0.2" />


	<material name="black">
    		<color rgba="0.0 0.0 0.0 1.0"/>
  	</material>

  	<material name="blue">
    		<color rgba="0.203125 0.23828125 0.28515625 1.0"/>
  	</material>

	<material name="green">
 	   <color rgba="0.0 0.8 0.0 1.0"/>
 	</material>
 	
	<material name="grey">
    		<color rgba="0.2 0.2 0.2 1.0"/>
  	</material>

  	<material name="orange">
    		<color rgba="1.0 0.423529411765 0.0392156862745 1.0"/>
  	</material>

  	<material name="brown">
    		<color rgba="0.870588235294 0.811764705882 0.764705882353 1.0"/>
  	</material>

  	<material name="red">
    		<color rgba="0.80078125 0.12890625 0.1328125 1.0"/>
  	</material>

  	<material name="white">
    		<color rgba="1.0 1.0 1.0 1.0"/>
  	</material>

	<link name = "base_link">
		<pose> 0, 0, 0, 0, 0, 0</pose>
		
		<inertial>
			<mass value = "5"/>
			<origin rpy ="0 0 0" xyz = "0, 0, 0"/>
			<inertia ixx="0.03954166" ixy="0" ixz="0" iyy="0.10620833" iyz="0"  izz="0.1062083"/>
		</inertial>
		<visual>
			<origin rpy ="0, 0, 0" xyz = "0, 0, 0"/>
			<geometry>
				<box size = "0.3, 0.3, 0.2"/>
			</geomertry>
			<material name = "blue"/>
	</visual>
		<collision>
			<geometry>
        		<box size="${baselen} ${width} ${bodylen}"/>
        	</geometry>
    	</collision>
	</link>
	
	

	<xacro:macro name = "wheel" params = "name reflect side">

		<link name =  "${name}">
			<visual>
				<origin xyz = "0, 0, 0" rpy = "1.57, 0, 0"/>
				<geometry>
					<cylinder len = "0.03" radius = "0.05">
				</geometry>
				<material name = "red"/>
			</visual>

			<collision>
				<origin xyz = "0, 0, 0" rpy = "1.57, 0, 0"/>
				<geometry>
					<cylinder len = "0.03" radius = "0.05">
				</geometry>
				<material name = "red"/>
			</collision>

			<inertial>
				<mass = "0.5"> 

				<inertia ixx="1.0" ixy="0.0" ixz="0.0" iyy="1.0" iyz="0.0" izz="1.0" />
			</inertial>
		</link>

		<joint name = "${name}_joint" type = "continuous">
			<axis xyz = "0, 1, 0" rpy = "0, 0, 0"/>
			<parent link = "base_link"/> 
			<child link = "name"/>
			<origin xyz = "${0.03*reflect/3} ${0.03/2*side} -${0.05/2+.05}" rpy="0 0 0"/>
"		<joint>
	
		<gazebo reference = "name">
			<mu1 value = ""/>
			<mu2 value = " "/>
			<kp vlaue = ""/>
			<kd value = ""/>
		</gazebo>

		<transmission name = "${name}_trans">
			<type> transmission_interface/SimpleTransmission</type>
			<actuator name = "${name}_wheel_motor">
				<mechanicalReduction>1</mechanicalReduction>
			</actuator>
			<joint name = "${name}_joint">
				<hardwareInterface>VelocityJointInterface</hardwareInterface>
			</joint>
		</transmission>

	</joint>
	
	</xacro:macro>
	<xacro:wheel name="left_front_wheel" reflect="1" side="1"/>
  	<xacro:wheel name="left_back_wheel" reflect="-1" side="1"/>
  	<xacro:wheel name="right_front_wheel" reflect="1" side="-1"/>
  	<xacro:wheel name="right_back_wheel" reflect="-1" side="-1"/>
  	<joint name="gripper_extension" type="prismatic">
    	<parent link="base_link"/>
    	<child link="gripper_pole"/>
    	<limit effort="1000.0" upper="0.6-.02" lower="0" velocity="0.2"/>
    	<origin rpy="0 0 0" xyz="0.2 0 0.05"/>
    	<limit effort="20" velocity="0.1"/>
  	</joint>


	<link name="gripper_pole">
    	<visual>
    		<geometry>
        		<cylinder length="0.25" radius="0.01"/>
        	</geometry>
      		<origin xyz="0.25 0 0" rpy="0 1.57 0 "/>
    	</visual>
    	<collision>
        	<geometry>
        		<cylinder length="0.25" radius="0.01"/>
        	</geometry>
        	<origin xyz="0.25 0 0" rpy="0 1.57 0 "/>
    	</collision>
    	<inertial>
				<mass = "0.5"> 

				<inertia ixx="1.0" ixy="0.0" ixz="0.0" iyy="1.0" iyz="0.0" izz="1.0" />
			</inertial>
		</link>

    
	<transmission name="gripper_extension_trans">
		<type>transmission_interface/SimpleTransmission</type>
    	<actuator name="gripper_extension_motor">
    		<mechanicalReduction>1</mechanicalReduction>
    	</actuator>
    	<joint name="gripper_extension">
    		<hardwareInterface>PositionJointInterface</hardwareInterface>
    	</joint>
	</transmission>

	<xacro:macro name="gripper" params="prefix reflect">
    <joint name="${prefix}_gripper_joint" type="revolute">
    	<axis xyz="0 0 ${reflect}"/>
      	<limit effort="1000.0" lower="0.0" upper="0.548" velocity="0.2"/>
      	<origin rpy="0 0 0" xyz="${polelen} ${reflect*0.01} 0"/>
      	<parent link="gripper_pole"/>
      	<child link="${prefix}_gripper"/>
      	<limit effort="30" velocity="1.0"/>
    </joint>

    <link name="${prefix}_gripper">
    	<visual>
        	<origin rpy="${(reflect-1)/2*pi} 0 0" xyz="0 0 0"/>
        	<geometry>
          		<mesh filename="package://urdf_tutorial/meshes/l_finger.dae"/>
        	</geometry>
      	</visual>
      	<collision>
        	<geometry>
          		<mesh filename="package://urdf_tutorial/meshes/l_finger.dae"/>
        	</geometry>
        	<origin rpy="${(reflect-1)/2*1.57} 0 0" xyz="0 0 0"/>
      	</collision>
    	<xacro:default_inertial mass="0.05"/>
    </link>

    <transmission name="${prefix}_gripper_trans">
    	<type>transmission_interface/SimpleTransmission</type>
      	<actuator name="${prefix}_gripper_motor">
        	<mechanicalReduction>1</mechanicalReduction>
      	</actuator>
      	<joint name="${prefix}_gripper_joint">
        	<hardwareInterface>PositionJointInterface</hardwareInterface>
      	</joint>
    </transmission>

    <joint name="${prefix}_tip_joint" type="fixed">
      	<parent link="${prefix}_gripper"/>
      	<child link="${prefix}_tip"/>
    </joint>
    <link name="${prefix}_tip">
      	<visual>
        	<origin rpy="${(reflect-1)/2*1.57} 0 0" xyz=" "/>
        	<geometry>
          <mesh filename="package://urdf_tutorial/meshes/l_finger_tip.dae"/>
        	</geometry>
      	</visual>
      	<collision>
        	<geometry>
          	<mesh filename="package://urdf_tutorial/meshes/l_finger_tip.dae"/>
        	</geometry>
        	<origin rpy="${(reflect-1)/2*1.57} 0 0" xyz=" "/>
      	</collision>
      	<xacro:default_inertial mass="0.05"/>
    	</link>
  	</xacro:macro>

  <xacro:gripper prefix="left" reflect="1" />
  <xacro:gripper prefix="right" reflect="-1" />

  <link name="camera">
    	<collision>
      		<origin xyz="0 0 0" rpy="0 0 0"/>
      		<geometry>
        		<box size="0.03 0.03 0.03"/>
      		</geometry>
    	</collision>

    <visual>
      	<origin xyz="0 0 0" rpy="0 0 0"/>
      	<geometry>
        	<box size="0.03 0.03 0.03"/>
      	</geometry>
      	<material name="white"/>
    </visual>

    <inertial>
      	<mass value="0.01" />
      	<origin xyz="0 0 0" rpy="0 0 0"/>
      	<box_inertia m="0.01" x="${cameraSize}" y="${cameraSize}" z="${cameraSize}" />
      	<inertia ixx="1e-2" ixy="0" ixz="0" iyy="1e-2" iyz="0" izz="1e-2" />
    </inertial>
  </link>

  <joint name="camera_joint" type="fixed">
	    <axis xyz="0 1 0" />
    	<origin xyz=".15 0 0" rpy="0 0 0"/>
    	<parent link="base_link"/>
    	<child link="camera"/>
  </joint>
	<gazebo>
    	<plugin name="gazebo_ros_control" filename="libgazebo_ros_control.so">
      		<robotNamespace>/mugator_manip</robotNamespace>
    		<robotSimType>gazebo_ros_control/DefaultRobotHWSim</robotSimType>
    		<legacyModeNS>true</legacyModeNS>
    	</plugin>
    </gazebo>
   	<gazebo reference="camera">
    	<material>Gazebo/Blue</material>
    	<sensor type="camera" name="camera">
      		<update_rate>20.0</update_rate>
      		<camera name="head">
        		<horizontal_fov>1.3962634</horizontal_fov>
        		<image>
          			<width>600</width>
          			<height>600</height>
          			<format>R8G8B8</format>
        		</image>
        		<clip>
	          		<near>0.03</near>
    	      		<far>250</far>
        		</clip>
      		</camera>

	      	<plugin name="camera_controller" filename="libgazebo_ros_camera.so">
			      <alwaysOn>true</alwaysOn>
	              <updateRate>0.0</updateRate>
    	   	  	  <cameraName>my_robot/camera</cameraName>
        	  	  <imageTopicName>image_raw</imageTopicName>
 	          	  <cameraInfoTopicName>camera_info</cameraInfoTopicName>
    	      	  <frameName>camera</frameName>
        	  	  <hackBaseline>0.07</hackBaseline>
 	          	  <distortionK1>0.0</distortionK1>
          	  	  <distortionK2>0.0</distortionK2>
              	  <distortionK3>0.0</distortionK3>
              	  <distortionT1>0.0</distortionT1>
            	  <distortionT2>0.0</distortionT2>
        	</plugin>
    	</sensor>
  </gazebo>








</robot>

	

